<!-- <?xml version="1.0" encoding="utf-8"?> -->
<!-- This URDF was automatically created by SolidWorks to URDF Exporter! Originally created by Stephen Brawner (brawner@gmail.com) 
     Commit Version: 1.6.0-4-g7f85cfe  Build Version: 1.6.7995.38578
     For more information, please see http://wiki.ros.org/sw_urdf_exporter -->
<robot
  name="my_robot">

  <!-- Base footprint (ground reference) -->
  <link name="base_footprint">
    <visual>
      <geometry>
        <box size="0.001 0.001 0.001"/>
      </geometry>
    </visual>
  </link>

  <!-- Fixed joint from base_footprint to base_link -->
  <joint name="base_footprint_joint" type="fixed">
    <parent link="base_footprint"/>
    <child link="base_link"/>
    <origin xyz="0 0 0.05" rpy="0 0 0"/>
  </joint>

  <link
    name="base_link">
    <inertial>
      <origin
        xyz="0 0 0.05"
        rpy="0 0 0" />
      <mass
        value="7.68" />
      <inertia
        ixx="0.043264"
        ixy="-2.7663E-18"
        ixz="-5.8775E-36"
        iyy="0.071936"
        iyz="-7.953E-35"
        izz="0.1024" />
    </inertial>
    <visual>
      <origin
        xyz="0 0 0"
        rpy="0 0 0" />
      <geometry>
        <mesh
          filename="package://my_robot/meshes/base_link.STL" />
      </geometry>
      <material
        name="">
        <color
          rgba="0.79216 0.81961 0.93333 1" />
      </material>
    </visual>
    <collision>
      <origin
        xyz="0 0 0"
        rpy="0 0 0" />
      <geometry>
        <mesh
          filename="package://my_robot/meshes/base_link.STL" />
      </geometry>
    </collision>
  </link>
  <link
    name="f_l_s">
    <inertial>
      <origin
        xyz="-5.5511E-17 0.00055205 -0.020526"
        rpy="0 0 0" />
      <mass
        value="0.3" />
      <inertia
        ixx="0.001"
        ixy="-8.6579E-23"
        ixz="1.0006E-22"
        iyy="0.001"
        iyz="1.7666E-07"
        izz="0.001" />
    </inertial>
    <visual>
      <origin
        xyz="0 0 0"
        rpy="0 0 0" />
      <geometry>
        <mesh
          filename="package://my_robot/meshes/f_l_s.STL" />
      </geometry>
      <material
        name="">
        <color
          rgba="0.79216 0.81961 0.93333 1" />
      </material>
    </visual>
    <collision>
      <origin
        xyz="0 0 0"
        rpy="0 0 0" />
      <geometry>
        <mesh
          filename="package://my_robot/meshes/f_l_s.STL" />
      </geometry>
    </collision>
  </link>
  <joint
    name="flsjoint"
    type="prismatic">
    <origin
      xyz="0.12 0.13 0.01822"
      rpy="0 0 0" />
    <parent
      link="base_link" />
    <child
      link="f_l_s" />
    <axis
      xyz="0 0 1" />
    <limit
      lower="0"
      upper="0.02"
      effort="50"
      velocity="1" />
    <dynamics
      damping="5"
      friction="0" />
  </joint>
  <link
    name="f_l_w">
    <inertial>
      <origin
        xyz="0 -0.022493 0"
        rpy="0 0 0" />
      <mass
        value="0.69233" />
      <inertia
        ixx="0.00096541"
        ixy="-2.1293E-23"
        ixz="-2.5388E-20"
        iyy="0.0016972"
        iyz="1.0189E-20"
        izz="0.00096541" />
    </inertial>
    <visual>
      <origin
        xyz="0 0 0"
        rpy="0 0 0" />
      <geometry>
        <mesh
          filename="package://my_robot/meshes/f_l_w.STL" />
      </geometry>
      <material
        name="">
        <color
          rgba="0.79216 0.81961 0.93333 1" />
      </material>
    </visual>
    <collision>
      <origin
        xyz="0 0 0"
        rpy="0 0 0" />
      <geometry>
        <mesh
          filename="package://my_robot/meshes/f_l_w.STL" />
      </geometry>
    </collision>
  </link>
  <joint
    name="flwjoint"
    type="continuous">
    <origin
      xyz="0 0.057 -0.04"
      rpy="0 0 0" />
    <parent
      link="f_l_s" />
    <child
      link="f_l_w" />
    <axis
      xyz="0 1 0" />
    <limit
      effort="15"
      velocity="8" />
    <dynamics
      damping="0.6"
      friction="0.15" />
  </joint>
  <link
    name="r_l_s">
    <inertial>
      <origin
        xyz="-1.3878E-17 0.00055205 -0.020526"
        rpy="0 0 0" />
      <mass
        value="0.3" />
      <inertia
        ixx="0.001"
        ixy="-3.3571E-23"
        ixz="-1.0438E-23"
        iyy="0.001"
        iyz="1.7666E-07"
        izz="0.001" />
    </inertial>
    <visual>
      <origin
        xyz="0 0 0"
        rpy="0 0 0" />
      <geometry>
        <mesh
          filename="package://my_robot/meshes/r_l_s.STL" />
      </geometry>
      <material
        name="">
        <color
          rgba="0.79216 0.81961 0.93333 1" />
      </material>
    </visual>
    <collision>
      <origin
        xyz="0 0 0"
        rpy="0 0 0" />
      <geometry>
        <mesh
          filename="package://my_robot/meshes/r_l_s.STL" />
      </geometry>
    </collision>
  </link>
  <joint
    name="rlsjoint"
    type="prismatic">
    <origin
      xyz="-0.12 0.13 0.01822"
      rpy="0 0 0" />
    <parent
      link="base_link" />
    <child
      link="r_l_s" />
    <axis
      xyz="0 0 1" />
    <limit
      lower="0"
      upper="0.02"
      effort="50"
      velocity="1" />
    <dynamics
      damping="5"
      friction="0" />
  </joint>
  <link
    name="r_l_w">
    <inertial>
      <origin
        xyz="-1.3878E-17 -0.022493 0"
        rpy="0 0 0" />
      <mass
        value="0.69233" />
      <inertia
        ixx="0.00096541"
        ixy="4.042E-20"
        ixz="1.5483E-20"
        iyy="0.0016972"
        iyz="1.4413E-23"
        izz="0.00096541" />
    </inertial>
    <visual>
      <origin
        xyz="0 0 0"
        rpy="0 0 0" />
      <geometry>
        <mesh
          filename="package://my_robot/meshes/r_l_w.STL" />
      </geometry>
      <material
        name="">
        <color
          rgba="0.79216 0.81961 0.93333 1" />
      </material>
    </visual>
    <collision>
      <origin
        xyz="0 0 0"
        rpy="0 0 0" />
      <geometry>
        <mesh
          filename="package://my_robot/meshes/r_l_w.STL" />
      </geometry>
    </collision>
  </link>
  <joint
    name="rlwjoint"
    type="continuous">
    <origin
      xyz="0 0.057 -0.04"
      rpy="0 0 0" />
    <parent
      link="r_l_s" />
    <child
      link="r_l_w" />
    <axis
      xyz="0 1 0" />
    <limit
      effort="15"
      velocity="8" />
    <dynamics
      damping="0.6"
      friction="0.15" />
  </joint>
  <link
    name="f_r_s">
    <inertial>
      <origin
        xyz="0 -0.00055205 -0.020526"
        rpy="0 0 0" />
      <mass
        value="0.3" />
      <inertia
        ixx="0.001"
        ixy="-5.3065E-23"
        ixz="-2.5662E-22"
        iyy="0.001"
        iyz="-1.7666E-07"
        izz="0.001" />
    </inertial>
    <visual>
      <origin
        xyz="0 0 0"
        rpy="0 0 0" />
      <geometry>
        <mesh
          filename="package://my_robot/meshes/f_r_s.STL" />
      </geometry>
      <material
        name="">
        <color
          rgba="0.79216 0.81961 0.93333 1" />
      </material>
    </visual>
    <collision>
      <origin
        xyz="0 0 0"
        rpy="0 0 0" />
      <geometry>
        <mesh
          filename="package://my_robot/meshes/f_r_s.STL" />
      </geometry>
    </collision>
  </link>
  <joint
    name="frsjoint"
    type="prismatic">
    <origin
      xyz="0.12 -0.13 0.01822"
      rpy="0 0 0" />
    <parent
      link="base_link" />
    <child
      link="f_r_s" />
    <axis
      xyz="0 0 1" />
    <limit
      lower="0"
      upper="0.02"
      effort="50"
      velocity="1" />
    <dynamics
      damping="5"
      friction="0" />
  </joint>
  <link
    name="f_r_w">
    <inertial>
      <origin
        xyz="0 0.022493 0"
        rpy="0 0 0" />
      <mass
        value="0.69233" />
      <inertia
        ixx="0.00096541"
        ixy="-1.0007E-20"
        ixz="7.9276E-20"
        iyy="0.0016972"
        iyz="-2.0113E-20"
        izz="0.00096541" />
    </inertial>
    <visual>
      <origin
        xyz="0 0 0"
        rpy="0 0 0" />
      <geometry>
        <mesh
          filename="package://my_robot/meshes/f_r_w.STL" />
      </geometry>
      <material
        name="">
        <color
          rgba="0.79216 0.81961 0.93333 1" />
      </material>
    </visual>
    <collision>
      <origin
        xyz="0 0 0"
        rpy="0 0 0" />
      <geometry>
        <mesh
          filename="package://my_robot/meshes/f_r_w.STL" />
      </geometry>
    </collision>
  </link>
  <joint
    name="frwjoint"
    type="continuous">
    <origin
      xyz="0 -0.057 -0.04"
      rpy="0 0 0" />
    <parent
      link="f_r_s" />
    <child
      link="f_r_w" />
    <axis
      xyz="0 1 0" />
    <limit
      effort="15"
      velocity="8" />
    <dynamics
      damping="0.6"
      friction="0.15" />
  </joint>
  <link
    name="r_r_s">
    <inertial>
      <origin
        xyz="0 -0.00055205 -0.020526"
        rpy="0 0 0" />
      <mass
        value="0.3" />
      <inertia
        ixx="0.001"
        ixy="-6.2652E-24"
        ixz="-3.0969E-22"
        iyy="0.001"
        iyz="-1.7666E-07"
        izz="0.001" />
    </inertial>
    <visual>
      <origin
        xyz="0 0 0"
        rpy="0 0 0" />
      <geometry>
        <mesh
          filename="package://my_robot/meshes/r_r_s.STL" />
      </geometry>
      <material
        name="">
        <color
          rgba="0.79216 0.81961 0.93333 1" />
      </material>
    </visual>
    <collision>
      <origin
        xyz="0 0 0"
        rpy="0 0 0" />
      <geometry>
        <mesh
          filename="package://my_robot/meshes/r_r_s.STL" />
      </geometry>
    </collision>
  </link>
  <joint
    name="rrsjoint"
    type="prismatic">
    <origin
      xyz="-0.12 -0.13 0.01822"
      rpy="0 0 0" />
    <parent
      link="base_link" />
    <child
      link="r_r_s" />
    <axis
      xyz="0 0 1" />
    <limit
      lower="0"
      upper="0.02"
      effort="50"
      velocity="1" />
    <dynamics
      damping="5"
      friction="0" />
  </joint>
  <link
    name="r_r_w">
    <inertial>
      <origin
        xyz="1.3878E-17 0.022493 0"
        rpy="0 0 0" />
      <mass
        value="0.69233" />
      <inertia
        ixx="0.00096541"
        ixy="-4.5973E-23"
        ixz="-3.6424E-20"
        iyy="0.0016972"
        iyz="5.0775E-21"
        izz="0.00096541" />
    </inertial>
    <visual>
      <origin
        xyz="0 0 0"
        rpy="0 0 0" />
      <geometry>
        <mesh
          filename="package://my_robot/meshes/r_r_w.STL" />
      </geometry>
      <material
        name="">
        <color
          rgba="0.79216 0.81961 0.93333 1" />
      </material>
    </visual>
    <collision>
      <origin
        xyz="0 0 0"
        rpy="0 0 0" />
      <geometry>
        <mesh
          filename="package://my_robot/meshes/r_r_w.STL" />
      </geometry>
    </collision>
  </link>
  <joint
    name="rrwjoint"
    type="continuous">
    <origin
      xyz="0 -0.057 -0.04"
      rpy="0 0 0" />
    <parent
      link="r_r_s" />
    <child
      link="r_r_w" />
    <axis
      xyz="0 1 0" />
    <limit
      effort="15"
      velocity="8" />
    <dynamics
      damping="0.6"
      friction="0.15" />
  </joint>
</robot>